Workbook

Sheet vs (thru Wed 740pm)
A1: rank | B1: player_name | C1: score
A2: 1 | B2: Ghostnova | C2: 15702055
A3: 2 | B3: kaazmaa | C3: 12214971
A4: 3 | B4: RaYYY | C4: 9119649
A5: 4 | B5: BEEEF | C5: 8611927
A6: 5 | B6: Medoosaa | C6: 8401268
A7: 6 | B7: Hokage IX | C7: 6311179
A8: 7 | B8: Loganc77 | C8: 6194536
A9: 8 | B9: RustyMaverick | C9: 6070432
A10: 9 | B10: Bonifacy lub Filemon | C10: 5827820
A11: 10 | B11: Eagle741 | C11: 5794630
A12: 11 | B12: Janeway44 | C12: 5693755
A13: 12 | B13: Acsoxg | C13: 5499645
... A97: 96 | B97: Thundrct | C97: 531480

Sheet power
A1: rank | B1: Player Name | C1: Score
A2: 1 | B2: Ghostnova | C2: 42986788
A3: 2 | B3: Eagle741 | C3: 38451162
A4: 3 | B4: Billtoppe | C4: 33500100
A5: 4 | B5: Medoosaa | C5: 30396271
A6: 5 | B6: Absolute Obam | C6: 28585390
A7: 6 | B7: Rogue Dahlia | C7: 26684639
A8: 7 | B8: 佐治挖泥 | C8: 26145694
A9: 8 | B9: Rembrandt00 | C9: 25648467
A10: 9 | B10: BEEEF | C10: 25323011
A11: 10 | B11: Shike Ryu | C11: 25115705
A12: 11 | B12: GatorsALegend | C12: 24106900
A13: 12 | B13: RustyMaverick | C13: 23874606
... A101: 100 | B101: emmy118 | C101: 1595038

Sheet analysis
A1: player_name | B1: VS | C1: Power | E1: VS | F1: Power | H1: Composite
A2: Ghostnova | B2: =VLOOKUP(A2,'vs (thru Wed 740pm)'!$B$2:$C$97,2,FALSE) -> 15702055 | C2: =VLOOKUP(A2,power!$B$2:$C$101,2,FALSE) -> 42986788 | E2: =PERCENTRANK(B$2:B$96,B2) -> 1 | F2: =PERCENTRANK(C$2:C$96,C2) -> 1 | H2: =+E2*F2*10000 -> 10000
A3: Eagle741 | B3: =VLOOKUP(A3,'vs (thru Wed 740pm)'!$B$2:$C$97,2,FALSE) -> 5794630 | C3: =VLOOKUP(A3,power!$B$2:$C$101,2,FALSE) -> 38451162 | E3: =PERCENTRANK(B$2:B$96,B3) -> 0.904 | F3: =PERCENTRANK(C$2:C$96,C3) -> 0.989 | H3: =+E3*F3*10000 -> 8940.56
A4: Billtoppe | B4: =VLOOKUP(A4,'vs (thru Wed 740pm)'!$B$2:$C$97,2,FALSE) -> 4737953 | C4: =VLOOKUP(A4,power!$B$2:$C$101,2,FALSE) -> 33500100 | E4: =PERCENTRANK(B$2:B$96,B4) -> 0.808 | F4: =PERCENTRANK(C$2:C$96,C4) -> 0.978 | H4: =+E4*F4*10000 -> 7902.24
A5: Medoosaa | B5: =VLOOKUP(A5,'vs (thru Wed 740pm)'!$B$2:$C$97,2,FALSE) -> 8401268 | C5: =VLOOKUP(A5,power!$B$2:$C$101,2,FALSE) -> 30396271 | E5: =PERCENTRANK(B$2:B$96,B5) -> 0.957 | F5: =PERCENTRANK(C$2:C$96,C5) -> 0.968 | H5: =+E5*F5*10000 -> 9263.76
A6: Absolute Obam | B6: =VLOOKUP(A6,'vs (thru Wed 740pm)'!$B$2:$C$97,2,FALSE) -> 4627335 | C6: =VLOOKUP(A6,power!$B$2:$C$101,2,FALSE) -> 28585390 | E6: =PERCENTRANK(B$2:B$96,B6) -> 0.776 | F6: =PERCENTRANK(C$2:C$96,C6) -> 0.957 | H6: =+E6*F6*10000 -> 7426.32
A7: Rogue Dahlia | B7: =VLOOKUP(A7,'vs (thru Wed 740pm)'!$B$2:$C$97,2,FALSE) -> 3641493 | C7: =VLOOKUP(A7,power!$B$2:$C$101,2,FALSE) -> 26684639 | E7: =PERCENTRANK(B$2:B$96,B7) -> 0.627 | F7: =PERCENTRANK(C$2:C$96,C7) -> 0.946 | H7: =+E7*F7*10000 -> 5931.42
A8: 佐治挖泥 | B8: =VLOOKUP(A8,'vs (thru Wed 740pm)'!$B$2:$C$97,2,FALSE) -> 2644035 | C8: =VLOOKUP(A8,power!$B$2:$C$101,2,FALSE) -> 26145694 | E8: =PERCENTRANK(B$2:B$96,B8) -> 0.414 | F8: =PERCENTRANK(C$2:C$96,C8) -> 0.936 | H8: =+E8*F8*10000 -> 3875.04
A9: Rembrandt00 | B9: =VLOOKUP(A9,'vs (thru Wed 740pm)'!$B$2:$C$97,2,FALSE) -> 3491725 | C9: =VLOOKUP(A9,power!$B$2:$C$101,2,FALSE) -> 25648467 | E9: =PERCENTRANK(B$2:B$96,B9) -> 0.606 | F9: =PERCENTRANK(C$2:C$96,C9) -> 0.925 | H9: =+E9*F9*10000 -> 5605.5
A10: BEEEF | B10: =VLOOKUP(A10,'vs (thru Wed 740pm)'!$B$2:$C$97,2,FALSE) -> 8611927 | C10: =VLOOKUP(A10,power!$B$2:$C$101,2,FALSE) -> 25323011 | E10: =PERCENTRANK(B$2:B$96,B10) -> 0.968 | F10: =PERCENTRANK(C$2:C$96,C10) -> 0.914 | H10: =+E10*F10*10000 -> 8847.52
A11: Shike Ryu | B11: 0 | C11: =VLOOKUP(A11,power!$B$2:$C$101,2,FALSE) -> 25115705 | E11: =PERCENTRANK(B$2:B$96,B11) -> 0 | F11: =PERCENTRANK(C$2:C$96,C11) -> 0.904 | H11: =+E11*F11*10000 -> 0
A12: GatorsALegend | B12: =VLOOKUP(A12,'vs (thru Wed 740pm)'!$B$2:$C$97,2,FALSE) -> 2853030 | C12: =VLOOKUP(A12,power!$B$2:$C$101,2,FALSE) -> 24106900 | E12: =PERCENTRANK(B$2:B$96,B12) -> 0.457 | F12: =PERCENTRANK(C$2:C$96,C12) -> 0.893 | H12: =+E12*F12*10000 -> 4081.01
A13: RustyMaverick | B13: =VLOOKUP(A13,'vs (thru Wed 740pm)'!$B$2:$C$97,2,FALSE) -> 6070432 | C13: =VLOOKUP(A13,power!$B$2:$C$101,2,FALSE) -> 23874606 | E13: =PERCENTRANK(B$2:B$96,B13) -> 0.925 | F13: =PERCENTRANK(C$2:C$96,C13) -> 0.882 | H13: =+E13*F13*10000 -> 8158.5
A14: BadApples | B14: =VLOOKUP(A14,'vs (thru Wed 740pm)'!$B$2:$C$97,2,FALSE) -> 3087825 | C14: =VLOOKUP(A14,power!$B$2:$C$101,2,FALSE) -> 23418217 | E14: =PERCENTRANK(B$2:B$96,B14) -> 0.489 | F14: =PERCENTRANK(C$2:C$96,C14) -> 0.872 | H14: =+E14*F14*10000 -> 4264.08
A15: Visgimir | B15: =VLOOKUP(A15,'vs (thru Wed 740pm)'!$B$2:$C$97,2,FALSE) -> 3810506 | C15: =VLOOKUP(A15,power!$B$2:$C$101,2,FALSE) -> 22782331 | E15: =PERCENTRANK(B$2:B$96,B15) -> 0.67 | F15: =PERCENTRANK(C$2:C$96,C15) -> 0.861 | H15: =+E15*F15*10000 -> 5768.7
A16: 라떼아이스2 | B16: =VLOOKUP(A16,'vs (thru Wed 740pm)'!$B$2:$C$97,2,FALSE) -> 3826667 | C16: =VLOOKUP(A16,power!$B$2:$C$101,2,FALSE) -> 22700462 | E16: =PERCENTRANK(B$2:B$96,B16) -> 0.68 | F16: =PERCENTRANK(C$2:C$96,C16) -> 0.851 | H16: =+E16*F16*10000 -> 5786.8
A17: Indiemeows | B17: =VLOOKUP(A17,'vs (thru Wed 740pm)'!$B$2:$C$97,2,FALSE) -> 3363330 | C17: =VLOOKUP(A17,power!$B$2:$C$101,2,FALSE) -> 22556083 | E17: =PERCENTRANK(B$2:B$96,B17) -> 0.574 | F17: =PERCENTRANK(C$2:C$96,C17) -> 0.84 | H17: =+E17*F17*10000 -> 4821.6
A18: GrannyT | B18: =VLOOKUP(A18,'vs (thru Wed 740pm)'!$B$2:$C$97,2,FALSE) -> 4546105 | C18: =VLOOKUP(A18,power!$B$2:$C$101,2,FALSE) -> 22343250 | E18: =PERCENTRANK(B$2:B$96,B18) -> 0.765 | F18: =PERCENTRANK(C$2:C$96,C18) -> 0.829 | H18: =+E18*F18*10000 -> 6341.85
A19: Acsoxg | B19: =VLOOKUP(A19,'vs (thru Wed 740pm)'!$B$2:$C$97,2,FALSE) -> 5499645 | C19: =VLOOKUP(A19,power!$B$2:$C$101,2,FALSE) -> 21970466 | E19: =PERCENTRANK(B$2:B$96,B19) -> 0.882 | F19: =PERCENTRANK(C$2:C$96,C19) -> 0.819 | H19: =+E19*F19*10000 -> 7223.58
A20: crabasourus | B20: =VLOOKUP(A20,'vs (thru Wed 740pm)'!$B$2:$C$97,2,FALSE) -> 4792980 | C20: =VLOOKUP(A20,power!$B$2:$C$101,2,FALSE) -> 21965627 | E20: =PERCENTRANK(B$2:B$96,B20) -> 0.84 | F20: =PERCENTRANK(C$2:C$96,C20) -> 0.808 | H20: =+E20*F20*10000 -> 6787.2
A21: kaazmaa | B21: =VLOOKUP(A21,'vs (thru Wed 740pm)'!$B$2:$C$97,2,FALSE) -> 12214971 | C21: =VLOOKUP(A21,power!$B$2:$C$101,2,FALSE) -> 21834920 | E21: =PERCENTRANK(B$2:B$96,B21) -> 0.989 | F21: =PERCENTRANK(C$2:C$96,C21) -> 0.797 | H21: =+E21*F21*10000 -> 7882.33
A22: Firekeeper01 | B22: =VLOOKUP(A22,'vs (thru Wed 740pm)'!$B$2:$C$97,2,FALSE) -> 3176420 | C22: =VLOOKUP(A22,power!$B$2:$C$101,2,FALSE) -> 21719679 | E22: =PERCENTRANK(B$2:B$96,B22) -> 0.531 | F22: =PERCENTRANK(C$2:C$96,C22) -> 0.787 | H22: =+E22*F22*10000 -> 4178.97
A23: GlokkGirl | B23: =VLOOKUP(A23,'vs (thru Wed 740pm)'!$B$2:$C$97,2,FALSE) -> 2158459 | C23: =VLOOKUP(A23,power!$B$2:$C$101,2,FALSE) -> 21474747 | E23: =PERCENTRANK(B$2:B$96,B23) -> 0.297 | F23: =PERCENTRANK(C$2:C$96,C23) -> 0.776 | H23: =+E23*F23*10000 -> 2304.72
... A42: Star2933 | B42: =VLOOKUP(A42,'vs (thru Wed 740pm)'!$B$2:$C$97,2,FALSE) -> 2722105 | C42: =VLOOKUP(A42,power!$B$2:$C$101,2,FALSE) -> 17966681 | E42: =PERCENTRANK(B$2:B$96,B42) -> 0.425 | F42: =PERCENTRANK(C$2:C$96,C42) -> 0.574 | H42: =+E42*F42*10000 -> 2439.5
A43: BulletBill2026 | B43: 0 | C43: =VLOOKUP(A43,power!$B$2:$C$101,2,FALSE) -> 17785133 | E43: =PERCENTRANK(B$2:B$96,B43) -> 0 | F43: =PERCENTRANK(C$2:C$96,C43) -> 0.563 | H43: =+E43*F43*10000 -> 0
A44: Raven2222 | B44: =VLOOKUP(A44,'vs (thru Wed 740pm)'!$B$2:$C$97,2,FALSE) -> 2034260 | C44: =VLOOKUP(A44,power!$B$2:$C$101,2,FALSE) -> 17705696 | E44: =PERCENTRANK(B$2:B$96,B44) -> 0.265 | F44: =PERCENTRANK(C$2:C$96,C44) -> 0.553 | H44: =+E44*F44*10000 -> 1465.45
A45: The big Bopper | B45: =VLOOKUP(A45,'vs (thru Wed 740pm)'!$B$2:$C$97,2,FALSE) -> 2851320 | C45: =VLOOKUP(A45,power!$B$2:$C$101,2,FALSE) -> 17590063 | E45: =PERCENTRANK(B$2:B$96,B45) -> 0.446 | F45: =PERCENTRANK(C$2:C$96,C45) -> 0.542 | H45: =+E45*F45*10000 -> 2417.32
A46: Thundrct | B46: =VLOOKUP(A46,'vs (thru Wed 740pm)'!$B$2:$C$97,2,FALSE) -> 531480 | C46: =VLOOKUP(A46,power!$B$2:$C$101,2,FALSE) -> 17540105 | E46: =PERCENTRANK(B$2:B$96,B46) -> 0.042 | F46: =PERCENTRANK(C$2:C$96,C46) -> 0.531 | H46: =+E46*F46*10000 -> 223.02
A47: Qarizma04 | B47: =VLOOKUP(A47,'vs (thru Wed 740pm)'!$B$2:$C$97,2,FALSE) -> 894740 | C47: =VLOOKUP(A47,power!$B$2:$C$101,2,FALSE) -> 17505236 | E47: =PERCENTRANK(B$2:B$96,B47) -> 0.085 | F47: =PERCENTRANK(C$2:C$96,C47) -> 0.521 | H47: =+E47*F47*10000 -> 442.85
A48: Bonifacy lub Filemon | B48: =VLOOKUP(A48,'vs (thru Wed 740pm)'!$B$2:$C$97,2,FALSE) -> 5827820 | C48: =VLOOKUP(A48,power!$B$2:$C$101,2,FALSE) -> 17439878 | E48: =PERCENTRANK(B$2:B$96,B48) -> 0.914 | F48: =PERCENTRANK(C$2:C$96,C48) -> 0.51 | H48: =+E48*F48*10000 -> 4661.4
A49: Chateez | B49: =VLOOKUP(A49,'vs (thru Wed 740pm)'!$B$2:$C$97,2,FALSE) -> 3135488 | C49: =VLOOKUP(A49,power!$B$2:$C$101,2,FALSE) -> 17282972 | E49: =PERCENTRANK(B$2:B$96,B49) -> 0.51 | F49: =PERCENTRANK(C$2:C$96,C49) -> 0.5 | H49: =+E49*F49*10000 -> 2550
A50: Kavaz25 | B50: =VLOOKUP(A50,'vs (thru Wed 740pm)'!$B$2:$C$97,2,FALSE) -> 4109114 | C50: =VLOOKUP(A50,power!$B$2:$C$101,2,FALSE) -> 17113163 | E50: =PERCENTRANK(B$2:B$96,B50) -> 0.723 | F50: =PERCENTRANK(C$2:C$96,C50) -> 0.489 | H50: =+E50*F50*10000 -> 3535.47
A51: AlleyBoss129453 | B51: =VLOOKUP(A51,'vs (thru Wed 740pm)'!$B$2:$C$97,2,FALSE) -> 2871198 | C51: =VLOOKUP(A51,power!$B$2:$C$101,2,FALSE) -> 17038910 | E51: =PERCENTRANK(B$2:B$96,B51) -> 0.468 | F51: =PERCENTRANK(C$2:C$96,C51) -> 0.478 | H51: =+E51*F51*10000 -> 2237.04
A52: JojoBest | B52: =VLOOKUP(A52,'vs (thru Wed 740pm)'!$B$2:$C$97,2,FALSE) -> 3160555 | C52: =VLOOKUP(A52,power!$B$2:$C$101,2,FALSE) -> 16866712 | E52: =PERCENTRANK(B$2:B$96,B52) -> 0.521 | F52: =PERCENTRANK(C$2:C$96,C52) -> 0.468 | H52: =+E52*F52*10000 -> 2438.28
A53: DarkSD03 | B53: =VLOOKUP(A53,'vs (thru Wed 740pm)'!$B$2:$C$97,2,FALSE) -> 2766515 | C53: =VLOOKUP(A53,power!$B$2:$C$101,2,FALSE) -> 16865076 | E53: =PERCENTRANK(B$2:B$96,B53) -> 0.436 | F53: =PERCENTRANK(C$2:C$96,C53) -> 0.457 | H53: =+E53*F53*10000 -> 1992.52
A54: Janeway44 | B54: =VLOOKUP(A54,'vs (thru Wed 740pm)'!$B$2:$C$97,2,FALSE) -> 5693755 | C54: =VLOOKUP(A54,power!$B$2:$C$101,2,FALSE) -> 16837866 | E54: =PERCENTRANK(B$2:B$96,B54) -> 0.893 | F54: =PERCENTRANK(C$2:C$96,C54) -> 0.446 | H54: =+E54*F54*10000 -> 3982.78
A55: xxRFRxx | B55: =VLOOKUP(A55,'vs (thru Wed 740pm)'!$B$2:$C$97,2,FALSE) -> 5314806 | C55: =VLOOKUP(A55,power!$B$2:$C$101,2,FALSE) -> 16613357 | E55: =PERCENTRANK(B$2:B$96,B55) -> 0.872 | F55: =PERCENTRANK(C$2:C$96,C55) -> 0.436 | H55: =+E55*F55*10000 -> 3801.92
... A77: Twinkletoes999 | B77: =VLOOKUP(A77,'vs (thru Wed 740pm)'!$B$2:$C$97,2,FALSE) -> 922725 | C77: =VLOOKUP(A77,power!$B$2:$C$101,2,FALSE) -> 13936106 | E77: =PERCENTRANK(B$2:B$96,B77) -> 0.095 | F77: =PERCENTRANK(C$2:C$96,C77) -> 0.202 | H77: =+E77*F77*10000 -> 191.9
A78: M15k | B78: 0 | C78: =VLOOKUP(A78,power!$B$2:$C$101,2,FALSE) -> 13586729 | E78: =PERCENTRANK(B$2:B$96,B78) -> 0 | F78: =PERCENTRANK(C$2:C$96,C78) -> 0.191 | H78: =+E78*F78*10000 -> 0
A79: NEP1ST0 | B79: =VLOOKUP(A79,'vs (thru Wed 740pm)'!$B$2:$C$97,2,FALSE) -> 2075935 | C79: =VLOOKUP(A79,power!$B$2:$C$101,2,FALSE) -> 13553595 | E79: =PERCENTRANK(B$2:B$96,B79) -> 0.287 | F79: =PERCENTRANK(C$2:C$96,C79) -> 0.18 | H79: =+E79*F79*10000 -> 516.6
...
